[ INFO/2021-07-10 13:49:50,829] hunter: 
                        Booting Up Please Wait
    
[ INFO/2021-07-10 13:49:50,831] hunter: Connecting Db
[ INFO/2021-07-10 13:50:01,563] hunter: Succesfully Established Connection With DataBase.
[ INFO/2021-07-10 13:50:01,629] telethon.network.mtprotosender: Connecting to 91.108.56.140:443/TcpFull...
[ INFO/2021-07-10 13:50:02,881] telethon.network.mtprotosender: Connection to 91.108.56.140:443/TcpFull complete!
[ INFO/2021-07-10 13:50:07,920] hunter: Loaded ~ extra
[ INFO/2021-07-10 13:50:07,924] hunter: Loaded ~ keyboard
[ INFO/2021-07-10 13:50:07,928] hunter: Loaded ~ memify
[ INFO/2021-07-10 13:50:07,932] hunter: Loaded ~ redis
[ INFO/2021-07-10 13:50:07,938] hunter: Loaded ~ start
[ INFO/2021-07-10 13:50:07,986] hunter: Loaded ~ sudo
[ INFO/2021-07-10 13:50:07,988] hunter: Loaded ~ __init__
[ERROR/2021-07-10 13:50:12,738] telethon.client.updates: Unhandled exception on carbon_api
Traceback (most recent call last):
  File "C:\Users\yuvij\AppData\Local\Programs\Python\Python39\lib\site-packages\selenium\webdriver\common\service.py", line 72, in start
    self.process = subprocess.Popen(cmd, env=self.env,
  File "C:\Users\yuvij\AppData\Local\Programs\Python\Python39\lib\subprocess.py", line 951, in __init__
    self._execute_child(args, executable, preexec_fn, close_fds,
  File "C:\Users\yuvij\AppData\Local\Programs\Python\Python39\lib\subprocess.py", line 1420, in _execute_child
    hp, ht, pid, tid = _winapi.CreateProcess(executable, args,
FileNotFoundError: [WinError 2] The system cannot find the file specified

During handling of the above exception, another exception occurred:

Traceback (most recent call last):
  File "C:\Users\yuvij\AppData\Local\Programs\Python\Python39\lib\site-packages\telethon\client\updates.py", line 454, in _dispatch_update
    await callback(event)
  File "C:\Users\yuvij\New folder\hunter\plugins\extra.py", line 205, in carbon_api
    driver = webdriver.Chrome(
  File "C:\Users\yuvij\AppData\Local\Programs\Python\Python39\lib\site-packages\selenium\webdriver\chrome\webdriver.py", line 73, in __init__
    self.service.start()
  File "C:\Users\yuvij\AppData\Local\Programs\Python\Python39\lib\site-packages\selenium\webdriver\common\service.py", line 81, in start
    raise WebDriverException(
selenium.common.exceptions.WebDriverException: Message: 'chromedriver' executable needs to be in PATH. Please see https://sites.google.com/a/chromium.org/chromedriver/home

